<?xml version="1.0" encoding="utf-8"?>
<!-- This URDF was automatically created by SolidWorks to URDF Exporter! Originally created by Stephen Brawner (brawner@gmail.com) 
     Commit Version: 1.5.1-0-g916b5db  Build Version: 1.5.7152.31018
     For more information, please see http://wiki.ros.org/sw_urdf_exporter -->
<robot
  name="awtube32010v2">
  <link
    name="base_link">
    <inertial>
      <origin
        xyz="-1 2 0.01132"
        rpy="0 0 0" />
      <mass
        value="18" />
      <inertia
        ixx="0.0066546"
        ixy="-2.18E-06"
        ixz="1.3E-07"
        iyy="0.00665"
        iyz="-3.2E-07"
        izz="0.01397" />
    </inertial>
    <visual>
      <origin
        xyz="0 0 0"
        rpy="0 0 0" />
      <geometry>
        <mesh
          filename="package://awtube32010v2/meshes/base_link.STL" />
      </geometry>
      <material
        name="">
        <color
          rgba="0.79216 0.81961 0.93333 1" />
      </material>
    </visual>
    <collision>
      <origin
        xyz="0 0 0"
        rpy="0 0 0" />
      <geometry>
        <mesh
          filename="package://awtube32010v2/meshes/controllo/base_link.STL" />
      </geometry>
    </collision>
  </link>
  <link
    name="link1">
    <inertial>
      <origin
        xyz="2E-05 0.00337 0.0783"
        rpy="0 0 0" />
      <mass
        value="17.11" />
      <inertia
        ixx="0.1"
        ixy="4.912E-05"
        ixz="9.505E-05"
        iyy="0.098412"
        iyz="0.00059172"
        izz="0.072655" />
    </inertial>
    <visual>
      <origin
        xyz="0 0 0"
        rpy="0 0 0" />
      <geometry>
        <mesh
          filename="package://awtube32010v2/meshes/link1.STL" />
      </geometry>
      <material
        name="">
        <color
          rgba="0.79216 0.81961 0.93333 1" />
      </material>
    </visual>
    <collision>
      <origin
        xyz="0 0 0"
        rpy="0 0 0" />
      <geometry>
        <mesh
          filename="package://awtube32010v2/meshes/controllo/link1.STL" />
      </geometry>
    </collision>
  </link>
  <joint
    name="joint1"
    type="revolute">
    <origin
      xyz="0 0 0.025"
      rpy="0 0 0" />
    <parent
      link="base_link" />
    <child
      link="link1" />
    <axis
      xyz="0 0 -1" />
    <limit
      lower="-3.14"
      upper="3.14"
      effort="627.3"
      velocity="2.074" />
    <dynamics
      damping="1"
      friction="0.1" />
  </joint>
  <link
    name="link2">
    <inertial>
      <origin
        xyz="0 0.221 0.127"
        rpy="0 0 0" />
      <mass
        value="37.96" />
      <inertia
        ixx="2.44"
        ixy="0.0001276"
        ixz="2.68E-06"
        iyy="0.2244"
        iyz="5.2692E-17"
        izz="2.37" />
    </inertial>
    <visual>
      <origin
        xyz="0 0 0"
        rpy="0 0 0" />
      <geometry>
        <mesh
          filename="package://awtube32010v2/meshes/link2.STL" />
      </geometry>
      <material
        name="">
        <color
          rgba="0.79216 0.81961 0.93333 1" />
      </material>
    </visual>
    <collision>
      <origin
        xyz="0 0 0"
        rpy="0 0 0" />
      <geometry>
        <mesh
          filename="package://awtube32010v2/meshes/controllo/link2.STL" />
      </geometry>
    </collision>
  </link>
  <joint
    name="joint2"
    type="revolute">
    <origin
      xyz="0 0.1045 0.092"
      rpy="1.5708 0 3.1416" />
    <parent
      link="link1" />
    <child
      link="link2" />
    <axis
      xyz="0 0 -1" />
    <limit
      lower="-3.14"
      upper="3.14"
      effort="627.3"
      velocity="1.244" />
    <dynamics
      damping="1"
      friction="0.1" />
  </joint>
  <link
    name="link3">
    <inertial>
      <origin
        xyz="-0.00146 -0.00018 0.12024"
        rpy="0 0 0" />
      <mass
        value="11.27" />
      <inertia
        ixx="0.058471"
        ixy="0.0001181"
        ixz="-0.00059134"
        iyy="0.075782"
        iyz="1.52E-05"
        izz="0.048306" />
    </inertial>
    <visual>
      <origin
        xyz="0 0 0"
        rpy="0 0 0" />
      <geometry>
        <mesh
          filename="package://awtube32010v2/meshes/link3.STL" />
      </geometry>
      <material
        name="">
        <color
          rgba="0.79216 0.81961 0.93333 1" />
      </material>
    </visual>
    <collision>
      <origin
        xyz="0 0 0"
        rpy="0 0 0" />
      <geometry>
        <mesh
          filename="package://awtube32010v2/meshes/controllo/link3.STL" />
      </geometry>
    </collision>
  </link>
  <joint
    name="joint3"
    type="revolute">
    <origin
      xyz="0 0.525 0.0505"
      rpy="-3.1416 0 -3.1416" />
    <parent
      link="link2" />
    <child
      link="link3" />
    <axis
      xyz="0 0 -1" />
    <limit
      lower="-3.14"
      upper="3.14"
      effort="368"
      velocity="2.074" />
    <dynamics
      damping="1"
      friction="0.1" />
  </joint>
  <link
    name="link4">
    <inertial>
      <origin
        xyz="0.00019 -0.00169 0.353"
        rpy="0 0 0" />
      <mass
        value="9.75" />
      <inertia
        ixx="1.0831"
        ixy="-0.000105"
        ixz="3.162E-05"
        iyy="0.090958"
        iyz="-0.00057054"
        izz="0.039951" />
    </inertial>
    <visual>
      <origin
        xyz="0 0 0"
        rpy="0 0 0" />
      <geometry>
        <mesh
          filename="package://awtube32010v2/meshes/link4.STL" />
      </geometry>
      <material
        name="">
        <color
          rgba="0.86667 0.86667 0.8902 1" />
      </material>
    </visual>
    <collision>
      <origin
        xyz="0 0 0"
        rpy="0 0 0" />
      <geometry>
        <mesh
          filename="package://awtube32010v2/meshes/controllo/link4.STL" />
      </geometry>
    </collision>
  </link>
  <joint
    name="joint4"
    type="revolute">
    <origin
      xyz="0.0874 0 0.155"
      rpy="-1.5708 0 -1.5708" />
    <parent
      link="link3" />
    <child
      link="link4" />
    <axis
      xyz="0 0 -1" />
    <limit
      lower="-3.14"
      upper="3.14"
      effort="151.3"
      velocity="2.844" />
    <dynamics
      damping="1"
      friction="0.1" />
  </joint>
  <link
    name="link5">
    <inertial>
      <origin
        xyz="2E-05 0.195 -0.06264"
        rpy="0 0 0" />
      <mass
        value="5.22" />
      <inertia
        ixx="0.04194"
        ixy="3.48E-06"
        ixz="-1.969E-05"
        iyy="0.020419"
        iyz="-0.0112"
        izz="0.034237" />
    </inertial>
    <visual>
      <origin
        xyz="0 0 0"
        rpy="0 3.14 3.14" />
      <geometry>
        <mesh
          filename="package://awtube32010v2/meshes/link5.STL" />
      </geometry>
      <material
        name="">
        <color
          rgba="0.69804 0.69804 0.69804 1" />
      </material>
    </visual>
    <collision>
      <origin
        xyz="0 0 0"
        rpy="0 3.14 3.14" />
      <geometry>
        <mesh
          filename="package://awtube32010v2/meshes/controllo/link5.STL" />
      </geometry>
    </collision>
  </link>
  <joint
    name="joint5"
    type="revolute">
    <origin
      xyz="0 0.0874 0.3876"
      rpy="1.5708 -1.5708 0" />
    <parent
      link="link4" />
    <child
      link="link5" />
    <axis
      xyz="0 0 -1" />
    <limit
      lower="-1.6"
      upper="1.6"
      effort="151.3"
      velocity="2.844" />
    <dynamics
      damping="1"
      friction="0.1" />
  </joint>
  <link
    name="link6">
    <inertial>
      <origin
        xyz="-0.00010981 1E-05 -0.0257"
        rpy="0 0 0" />
      <mass
        value="0.41" />
      <inertia
        ixx="0.00033"
        ixy="-1.2E-07"
        ixz="9.4E-07"
        iyy="0.000328"
        iyz="6E-08"
        izz="0.00054" />
    </inertial>
    <visual>
      <origin
        xyz="0 0 0"
        rpy="0 0 0" />
      <geometry>
        <mesh
          filename="package://awtube32010v2/meshes/link6.STL" />
      </geometry>
      <material
        name="">
        <color
          rgba="0.8902 0.8902 0.91373 1" />
      </material>
    </visual>
    <collision>
      <origin
        xyz="0 0 0"
        rpy="0 0 0" />
      <geometry>
        <mesh
          filename="package://awtube32010v2/meshes/controllo/link6.STL" />
      </geometry>
    </collision>
  </link>
  <joint
    name="joint6"
    type="revolute">
    <origin
      xyz="0 -0.328 0.0911"
      rpy="1.5708 0 0" />
    <parent
      link="link5" />
    <child
      link="link6" />
    <axis
      xyz="0 0 -1" />
    <limit
      lower="-3.14"
      upper="3.14"
      effort="62"
      velocity="5.75" />
    <dynamics
      damping="1"
      friction="0.1" />
  </joint>
</robot>