<?xml version="1.0" encoding="utf-8"?>
<!--
  ~ Copyright (c) 2024. Glowbuzzer. All rights reserved
  -->

<!-- This URDF was automatically created by SolidWorks to URDF Exporter! Originally created by Stephen Brawner (brawner@gmail.com)
     Commit Version: 1.5.1-0-g916b5db  Build Version: 1.5.7152.31018
     For more information, please see http://wiki.ros.org/sw_urdf_exporter -->
<robot
  name="awtube362010v3">
  <link
    name="base_link">
    <inertial>
      <origin
        xyz="0 0 0.0122"
        rpy="0 0 0" />
      <mass
        value="1.95" />
      <inertia
        ixx="0.0069682"
        ixy="-2.18E-06"
        ixz="1.4E-07"
        iyy="0.00696385"
        iyz="-34E-07"
        izz="0.01362583" />
    </inertial>
    <visual>
      <origin
        xyz="0 0 0"
        rpy="0 0 0" />
      <geometry>
        <mesh
          filename="package://awtube362010v3/meshes/base_link.STL" />
      </geometry>
      <material
        name="">
        <color
          rgba="0.79216 0.81961 0.93333 1" />
      </material>
    </visual>
    <collision>
      <origin
        xyz="0 0 0"
        rpy="0 0 0" />
      <geometry>
        <mesh
          filename="package://awtube362010v3/meshes/base_link.STL" />
      </geometry>
    </collision>
  </link>
  <link
    name="link1">
    <inertial>
      <origin
        xyz="0 0.00689 0.075"
        rpy="0 0 0" />
      <mass
        value="16.69" />
      <inertia
        ixx="0.10217919"
        ixy="5.16E-05"
        ixz="7.53E-06"
        iyy="0.09590711"
        iyz="0.00170785"
        izz="0.07689061" />
    </inertial>
    <visual>
      <origin
        xyz="0 0 0"
        rpy="0 0 0" />
      <geometry>
        <mesh
          filename="package://awtube362010v3/meshes/link1.STL" />
      </geometry>
      <material
        name="">
        <color
          rgba="0.79216 0.81961 0.93333 1" />
      </material>
    </visual>
    <collision>
      <origin
        xyz="0 0 0"
        rpy="0 0 0" />
      <geometry>
        <mesh
          filename="package://awtube362010v3/meshes/link1.STL" />
      </geometry>
    </collision>
  </link>
  <joint
    name="joint1"
    type="revolute">
    <origin
      xyz="0 0 0.025"
      rpy="0 0 0" />
    <parent
      link="base_link" />
    <child
      link="link1" />
    <axis
      xyz="0 0 -1" />
    <limit
      lower="-3.14"
      upper="3.14"
      effort="627.3"
      velocity="2.074" />
    <dynamics
      damping="1"
      friction="0.1" />
  </joint>
  <link
    name="link2">
    <inertial>
      <origin
        xyz="0 0.22573 0.12924"
        rpy="0 0 0" />
      <mass
        value="39.11" />
      <inertia
        ixx="2.53770133"
        ixy="0.00036004"
        ixz="2.83E-06"
        iyy="0.23568053"
        iyz="0.11447746"
        izz="2.45787606" />
    </inertial>
    <visual>
      <origin
        xyz="0 0 0"
        rpy="0 0 0" />
      <geometry>
        <mesh
          filename="package://awtube362010v3/meshes/link2.STL" />
      </geometry>
      <material
        name="">
        <color
          rgba="0.79216 0.81961 0.93333 1" />
      </material>
    </visual>
    <collision>
      <origin
        xyz="0 0 0"
        rpy="0 0 0" />
      <geometry>
        <mesh
          filename="package://awtube362010v3/meshes/link2.STL" />
      </geometry>
    </collision>
  </link>
  <joint
    name="joint2"
    type="revolute">
    <origin
      xyz="0 0.1045 0.092"
      rpy="1.5708 0 3.1416" />
    <parent
      link="link1" />
    <child
      link="link2" />
    <axis
      xyz="0 0 -1" />
    <limit
      lower="-3.14"
      upper="3.14"
      effort="627.3"
      velocity="1.244" />
    <dynamics
      damping="1"
      friction="0.1" />
  </joint>
  <link
    name="link3">
    <inertial>
      <origin
        xyz="-0.00435 -0.00024 0.12101"
        rpy="0 0 0" />
      <mass
        value="11.63" />
      <inertia
        ixx="0.05939058"
        ixy="0.00020876"
        ixz="-0.00172215"
        iyy="0.07945952"
        iyz="-7.78E-06"
        izz="0.05197227" />
    </inertial>
    <visual>
      <origin
        xyz="0 0 0"
        rpy="0 0 0" />
      <geometry>
        <mesh
          filename="package://awtube362010v3/meshes/link3.STL" />
      </geometry>
      <material
        name="">
        <color
          rgba="0.79216 0.81961 0.93333 1" />
      </material>
    </visual>
    <collision>
      <origin
        xyz="0 0 0"
        rpy="0 0 0" />
      <geometry>
        <mesh
          filename="package://awtube362010v3/meshes/link3.STL" />
      </geometry>
    </collision>
  </link>
  <joint
    name="joint3"
    type="revolute">
    <origin
      xyz="0 0.525 0.0505"
      rpy="-3.1416 0 -3.1416" />
    <parent
      link="link2" />
    <child
      link="link3" />
    <axis
      xyz="0 0 -1" />
    <limit
      lower="-3.14"
      upper="3.14"
      effort="368"
      velocity="2.074" />
    <dynamics
      damping="1"
      friction="0.1" />
  </joint>
  <link
    name="link4">
    <inertial>
      <origin
        xyz="0.00026 -0.00501 0.35486"
        rpy="0 0 0" />
      <mass
        value="10.12" />
      <inertia
        ixx="0.11192934"
        ixy="-0.00019588"
        ixz="5.362E-05"
        iyy="0.09184952"
        iyz="-0.00165351"
        izz="0.04359029" />
    </inertial>
    <visual>
      <origin
        xyz="0 0 0"
        rpy="0 0 0" />
      <geometry>
        <mesh
          filename="package://awtube362010v3/meshes/link4.STL" />
      </geometry>
      <material
        name="">
        <color
          rgba="0.86667 0.86667 0.8902 1" />
      </material>
    </visual>
    <collision>
      <origin
        xyz="0 0 0"
        rpy="0 0 0" />
      <geometry>
        <mesh
          filename="package://awtube362010v3/meshes/link4.STL" />
      </geometry>
    </collision>
  </link>
  <joint
    name="joint4"
    type="revolute">
    <origin
      xyz="0.0874 0 0.155"
      rpy="-1.5708 0 -1.5708" />
    <parent
      link="link3" />
    <child
      link="link4" />
    <axis
      xyz="0 0 -1" />
    <limit
      lower="-3.14"
      upper="3.14"
      effort="151.3"
      velocity="2.844" />
    <dynamics
      damping="1"
      friction="0.1" />
  </joint>
  <link
    name="link5">
    <inertial>
      <origin
        xyz="0 -0.1926 0.06426"
        rpy="0 0 0" />
      <mass
        value="5.53" />
      <inertia
        ixx="0.04307947"
        ixy="-1.218E-05"
        ixz="1.734E-05"
        iyy="0.0072992"
        iyz="-0.01088632"
        izz="0.03471329" />
    </inertial>
    <visual>
      <origin
        xyz="0 0 0"
        rpy="0 0 0" />
      <geometry>
        <mesh
          filename="package://awtube362010v3/meshes/link5.STL" />
      </geometry>
      <material
        name="">
        <color
          rgba="0.69804 0.69804 0.69804 1" />
      </material>
    </visual>
    <collision>
      <origin
        xyz="0 0 0"
        rpy="0 0 0" />
      <geometry>
        <mesh
          filename="package://awtube362010v3/meshes/link5.STL" />
      </geometry>
    </collision>
  </link>
  <joint
    name="joint5"
    type="revolute">
    <origin
      xyz="0 0.0874 0.3876"
      rpy="1.5708 -1.5708 0" />
    <parent
      link="link4" />
    <child
      link="link5" />
    <axis
      xyz="0 0 1" />
    <limit
      lower="-1.6"
      upper="1.6"
      effort="151.3"
      velocity="2.844" />
    <dynamics
      damping="1"
      friction="0.1" />
  </joint>
  <link
    name="link6">
    <inertial>
      <origin
        xyz="0 -0.00011 -0.0257"
        rpy="0 0 0" />
      <mass
        value="0.41" />
      <inertia
        ixx="0.00032842"
        ixy="-5.9E-07"
        ixz="-3.2E-07"
        iyy="0.00032983"
        iyz="-8.9E-07"
        izz="0.00054011" />
    </inertial>
    <visual>
      <origin
        xyz="0 0 0"
        rpy="0 0 0" />
      <geometry>
        <mesh
          filename="package://awtube362010v3/meshes/link6.STL" />
      </geometry>
      <material
        name="">
        <color
          rgba="0.8902 0.8902 0.91373 1" />
      </material>
    </visual>
    <collision>
      <origin
        xyz="0 0 0"
        rpy="0 0 0" />
      <geometry>
        <mesh
          filename="package://awtube362010v3/meshes/link6.STL" />
      </geometry>
    </collision>
  </link>
  <joint
    name="joint6"
    type="revolute">
    <origin
      xyz="0 -0.328 0.0911"
      rpy="1.5708 0 0" />
    <parent
      link="link5" />
    <child
      link="link6" />
    <axis
      xyz="0 0 -1" />
    <limit
      lower="-3.14"
      upper="3.14"
      effort="62"
      velocity="5.75" />
    <dynamics
      damping="1"
      friction="0.1" />
  </joint>
</robot>
